{"Launchpad":"https://bugs.launchpad.net/bugs/1398078","Id":"1398078","Gerrit":"https://review.openstack.org/147566","IdGerrit":"147566","IdCommit":"4dc367f7d736ae506db9532270e92977c8b3954d","Files":["cinder/volume/targets/tgt.py"],"Lines_Inseted":16,"Lines_Deleted":12,"CommitParent":"59b4123043f3fd9d3f05a3e8bfb969b81c3f7db6","Classification":"Bug","KeywordsTitle":"failed","Description":"bug, error message, not tracking","KeywordsCommit":"add retry, creation, create, update, have issues, error, exists failure, break out, call","Comments":""}