{"Launchpad":"https://bugs.launchpad.net/bugs/1437419","Id":"1437419","Gerrit":"https://review.openstack.org/172172","IdGerrit":"172172","IdCommit":"78dc8fa9b2e60be1f901a50249d8e9b6274e3fa4","Files":["cinder/tests/test_netapp.py","cinder/volume/drivers/netapp/api.py","cinder/volume/drivers/netapp/iscsi.py"],"Lines_Inseted":88,"Lines_Deleted":18,"CommitParent":"a3e4439de2b153341c27eb8c700632cd15fdb473","Classification":"Bug","KeywordsTitle":"fails, failover","Description":"errors out, failed, failure","KeywordsCommit":"failover mode, attempt fail,","Comments":""}