{"Launchpad":"https://bugs.launchpad.net/bugs/1477027","Id":"1477027","Gerrit":"https://review.openstack.org/204702","IdGerrit":"204702","IdCommit":"eccf433fd716ac5f61cafbb490ddeed0a6827531","Files":["cinder/tests/unit/volume/drivers/netapp/eseries/test_library.py","cinder/volume/drivers/netapp/eseries/library.py"],"Lines_Inseted":1,"Lines_Deleted":1,"CommitParent":"94e3098238f4af32f6ffa85833d0107cab07c14c","Classification":"Bug","KeywordsTitle":"raises NetAppDriverException, does not exist","Description":"error, exeption","KeywordsCommit":"fixes bug, KeyError Exception, incosistent state","Comments":""}