{"Launchpad":"https://bugs.launchpad.net/bugs/1478737","Id":"1478737","Gerrit":"https://review.openstack.org/206645","IdGerrit":"206645","IdCommit":"beef71d0f8edf5770f8fe95d85e5ea230ddd6f10","Files":["cinder/image/glance.py","cinder/tests/unit/glance/stubs.py","cinder/tests/unit/image/test_glance.py"],"Lines_Inseted":2,"Lines_Deleted":2,"CommitParent":"d620337353ee9470824d5f07798ee8d01c4c88fc","Classification":"Bug","KeywordsTitle":"fails","Description":"throw a stacktrace","KeywordsCommit":"fix exception, adds","Comments":""}