{"Launchpad":"https://bugs.launchpad.net/bugs/1497868","Id":"1497868","Gerrit":"https://review.openstack.org/226149","IdGerrit":"226149","IdCommit":"4bdeb045e491a86aeb8a1487798e598a2fa56e2f","Files":["cinder/api/contrib/used_limits.py","cinder/tests/unit/api/contrib/test_used_limits.py"],"Lines_Inseted":16,"Lines_Deleted":17,"CommitParent":"cbb55074de48176cbaa3f31a5b1d595b8aad7aa8","Classification":"Bug","KeywordsTitle":"failed","Description":"will be failed, error, Forbidden error, bug","KeywordsCommit":"fix","Comments":""}