{"Launchpad":"https://bugs.launchpad.net/bugs/1497007","Id":"1497007","Gerrit":"https://review.openstack.org/233234","IdGerrit":"233234","IdCommit":"1b4e2e7a48ec76fa5bc80b13fc4a04bce660ad31","Files":["cinder/tests/unit/volume/drivers/netapp/eseries/fakes.py","cinder/tests/unit/volume/drivers/netapp/eseries/test_client.py","cinder/tests/unit/volume/drivers/netapp/eseries/test_library.py","cinder/volume/drivers/netapp/eseries/client.py","cinder/volume/drivers/netapp/eseries/library.py"],"Lines_Inseted":94,"Lines_Deleted":30,"CommitParent":"170aac0ab03cc2626db0746fdc6a39fa2e775913","Classification":"Bug","KeywordsTitle":"not updating correctly","Description":"not occurring, fail","KeywordsCommit":"fix, validity checking, refactors, to be more concise, adds additional unittests","Comments":""}