{"Launchpad":"https://bugs.launchpad.net/bugs/1504718","Id":"1504718","Gerrit":"https://review.openstack.org/233333","IdGerrit":"233333","IdCommit":"3e9cc4fc5f8e82021b3bfd3106d3e50d2caaf91a","Files":["cinder/tests/unit/test_huawei_drivers.py","cinder/volume/drivers/huawei/constants.py","cinder/volume/drivers/huawei/rest_client.py"],"Lines_Inseted":5,"Lines_Deleted":0,"CommitParent":"c06a0f822e89a96768ba4f6202ddf12181773c02","Classification":"Bug","KeywordsTitle":"create_volume when it already exits","Description":"create a volume but it already exits, gets fault, raise an exeption","KeywordsCommit":"handle exists error, exeption","Comments":""}