{"Launchpad":"https://bugs.launchpad.net/bugs/1506422","Id":"1506422","Gerrit":"https://review.openstack.org/235197","IdGerrit":"235197","IdCommit":"882175e37b4f184dd0996c14afdae744fc36a7cc","Files":["cinder/tests/unit/test_vmware_vmdk.py","cinder/volume/drivers/vmware/vmdk.py","cinder/volume/drivers/vmware/volumeops.py"],"Lines_Inseted":58,"Lines_Deleted":69,"CommitParent":"3b0fcc3e758b6763d93aa2cea40aa46748201e99","Classification":"Bug","KeywordsTitle":"relocated, fault","Description":"shouldn't attempt to relocate, fail","KeywordsCommit":"fixes the issue, also refactors","Comments":""}