{"Launchpad":"https://bugs.launchpad.net/bugs/1506496","Id":"1506496","Gerrit":"https://review.openstack.org/235401","IdGerrit":"235401","IdCommit":"fdcd66eaf9b23f72438016c86d80c504107b0dfb","Files":["cinder/cmd/rtstool.py"],"Lines_Inseted":3,"Lines_Deleted":2,"CommitParent":"ec98796767d1d743a30767edb9a1f3bb7d4deba8","Classification":"Not_Bug","KeywordsTitle":"don't fail","Description":"getting out of sync, allow to succeed rather than failing, error","KeywordsCommit":" should not raise an error if it can't find the initiator, the teardown should be allowed to succeed","Comments":""}