{"Launchpad":"https://bugs.launchpad.net/bugs/1506940","Id":"1506940","Gerrit":"https://review.openstack.org/252018","IdGerrit":"252018","IdCommit":"d3412d0c06a001c8158dee22f50b2e22b2d5c7f5","Files":["cinder/tests/unit/volume/drivers/netapp/eseries/test_library.py","cinder/volume/drivers/netapp/eseries/library.py"],"Lines_Inseted":20,"Lines_Deleted":0,"CommitParent":"08a8eb7d59238bb4cc9ef62833849d8478360c91","Classification":"Bug","KeywordsTitle":" potential cleanup on failed volume create","Description":"if volume fails it doesn't clean up, leaving a partially created volume, tries ti recreate, error","KeywordsCommit":"volume create fails","Comments":""}