{"Launchpad":"https://bugs.launchpad.net/bugs/1510790","Id":"1510790","Gerrit":"https://review.openstack.org/239837","IdGerrit":"239837","IdCommit":"99dc6d34754954a27f6998406a94743c41b93981","Files":["cinder/compute/nova.py"],"Lines_Inseted":2,"Lines_Deleted":2,"CommitParent":"cbb55074de48176cbaa3f31a5b1d595b8aad7aa8","Classification":"Bug","KeywordsTitle":"unit tests failed","Description":"","KeywordsCommit":"Handle correct exception","Comments":""}